<?xml version="1.0" encoding="utf-8"?>
<!-- This URDF was automatically created by SolidWorks to URDF Exporter! Originally created by Stephen Brawner (brawner@gmail.com) 
     Commit Version: 1.6.0-4-g7f85cfe  Build Version: 1.6.7995.38578
     For more information, please see http://wiki.ros.org/sw_urdf_exporter -->
<robot
  name="taurus_description">
  <link
    name="base_link">
    <inertial>
      <origin
        xyz="0.323513290580689 0.109909851454141 0.0273636827046401"
        rpy="0 0 0" />
      <mass
        value="0.109923704165007" />
      <inertia
        ixx="8.50009197810057E-05"
        ixy="-1.86085775017922E-07"
        ixz="3.57248183955067E-07"
        iyy="0.00014440100030123"
        iyz="-3.65582256475082E-07"
        izz="6.25023471997517E-05" />
    </inertial>
    <visual>
      <origin
        xyz="0 0 0"
        rpy="0 0 0" />
      <geometry>
        <mesh
          filename="package://taurus_description/meshes/base_link.STL" />
      </geometry>
      <material
        name="">
        <color
          rgba="0.745098039215686 0.737254901960784 0.729411764705882 1" />
      </material>
    </visual>
    <collision>
      <origin
        xyz="0 0 0"
        rpy="0 0 0" />
      <geometry>
        <mesh
          filename="package://taurus_description/meshes/base_link.STL" />
      </geometry>
    </collision>
  </link>
  <link
    name="Rueda_derecha_link">
    <inertial>
      <origin
        xyz="-6.8527E-05 -1.7015E-08 0.012107"
        rpy="0 0 0" />
      <mass
        value="0.010873" />
      <inertia
        ixx="1.181E-06"
        ixy="1.6996E-12"
        ixz="2.0191E-09"
        iyy="1.1758E-06"
        iyz="7.7776E-15"
        izz="1.5164E-06" />
    </inertial>
    <visual>
      <origin
        xyz="0 0 0"
        rpy="0 0 0" />
      <geometry>
        <mesh
          filename="package://taurus_description/meshes/Rueda_derecha_link.STL" />
      </geometry>
      <material
        name="">
        <color
          rgba="0.29804 0.29804 0.29804 1" />
      </material>
    </visual>
    <collision>
      <origin
        xyz="0 0 0"
        rpy="0 0 0" />
      <geometry>
        <mesh
          filename="package://taurus_description/meshes/Rueda_derecha_link.STL" />
      </geometry>
    </collision>
  </link>
  <joint
    name="Rueda_derecha_joint"
    type="continuous">
    <origin
      xyz="0.26401 -0.020126 0.10147"
      rpy="0.0001876 -1.5693 -3.1416" />
    <parent
      link="base_link" />
    <child
      link="Rueda_derecha_link" />
    <axis
      xyz="0 0 1" />
  </joint>
  <link
    name="Rueda_izquierda_link">
    <inertial>
      <origin
        xyz="-6.8527E-05 -1.6996E-08 -0.010976"
        rpy="0 0 0" />
      <mass
        value="0.010873" />
      <inertia
        ixx="1.181E-06"
        ixy="1.6982E-12"
        ixz="2.0191E-09"
        iyy="1.1758E-06"
        iyz="7.2168E-15"
        izz="1.5164E-06" />
    </inertial>
    <visual>
      <origin
        xyz="0 0 0"
        rpy="0 0 0" />
      <geometry>
        <mesh
          filename="package://taurus_description/meshes/Rueda_izquierda_link.STL" />
      </geometry>
      <material
        name="">
        <color
          rgba="0.29804 0.29804 0.29804 1" />
      </material>
    </visual>
    <collision>
      <origin
        xyz="0 0 0"
        rpy="0 0 0" />
      <geometry>
        <mesh
          filename="package://taurus_description/meshes/Rueda_izquierda_link.STL" />
      </geometry>
    </collision>
  </link>
  <joint
    name="Rueda_izquierda_joint"
    type="continuous">
    <origin
      xyz="0.36027 -0.020097 0.1016"
      rpy="3.1414 1.5693 0" />
    <parent
      link="base_link" />
    <child
      link="Rueda_izquierda_link" />
    <axis
      xyz="0 0 1" />
  </joint>
  <link
    name="Scan_link">
    <inertial>
      <origin
        xyz="0.000885457600863837 -0.000140038629656364 0.0100581985144375"
        rpy="0 0 0" />
      <mass
        value="0.00557152535083265" />
      <inertia
        ixx="2.35900215808513E-07"
        ixy="-6.46042117643978E-10"
        ixz="-3.62802799005922E-08"
        iyy="6.4739513423399E-07"
        iyz="-3.25890135837136E-09"
        izz="5.64993685064317E-07" />
    </inertial>
    <visual>
      <origin
        xyz="0 0 0"
        rpy="0 0 0" />
      <geometry>
        <mesh
          filename="package://taurus_description/meshes/Scan_link.STL" />
      </geometry>
      <material
        name="">
        <color
          rgba="0.792156862745098 0.819607843137255 0.933333333333333 1" />
      </material>
    </visual>
    <collision>
      <origin
        xyz="0 0 0"
        rpy="0 0 0" />
      <geometry>
        <mesh
          filename="package://taurus_description/meshes/Scan_link.STL" />
      </geometry>
    </collision>
  </link>
  <joint
    name="Scan_joint"
    type="fixed">
    <origin
      xyz="0.32379 -0.064246 0.10987"
      rpy="-1.5722 0.001918 -3.1414" />
    <parent
      link="base_link" />
    <child
      link="Scan_link" />
    <axis
      xyz="0 0 0" />
  </joint>
  <link
    name="Base_castor_link">
    <inertial>
      <origin
        xyz="0.0065742 -0.0049742 -1.8068E-07"
        rpy="0 0 0" />
      <mass
        value="0.00033463" />
      <inertia
        ixx="6.3206E-09"
        ixy="1.7295E-10"
        ixz="-4.7653E-13"
        iyy="1.0328E-08"
        iyz="-1.3617E-14"
        izz="6.9193E-09" />
    </inertial>
    <visual>
      <origin
        xyz="0 0 0"
        rpy="0 0 0" />
      <geometry>
        <mesh
          filename="package://taurus_description/meshes/Base_castor_link.STL" />
      </geometry>
      <material
        name="">
        <color
          rgba="0 0 0 1" />
      </material>
    </visual>
    <collision>
      <origin
        xyz="0 0 0"
        rpy="0 0 0" />
      <geometry>
        <mesh
          filename="package://taurus_description/meshes/Base_castor_link.STL" />
      </geometry>
    </collision>
  </link>
  <joint
    name="Base_castor_joint"
    type="fixed">
    <origin
      xyz="0.31693 -0.080982 0.090912"
      rpy="-1.5676 -0.0014801 0" />
    <parent
      link="base_link" />
    <child
      link="Base_castor_link" />
    <axis
      xyz="0 0 0" />
  </joint>
  <link
    name="Caster_ball_link">
    <inertial>
      <origin
        xyz="0.0066086 -0.0049888 -0.00032894"
        rpy="0 0 0" />
      <mass
        value="0.00042116" />
      <inertia
        ixx="3.6426E-09"
        ixy="-3.0292E-27"
        ixz="-7.7548E-26"
        iyy="3.6426E-09"
        iyz="1.2925E-26"
        izz="3.6426E-09" />
    </inertial>
    <visual>
      <origin
        xyz="0 0 0"
        rpy="0 0 0" />
      <geometry>
        <mesh
          filename="package://taurus_description/meshes/Caster_ball_link.STL" />
      </geometry>
      <material
        name="">
        <color
          rgba="1 1 1 1" />
      </material>
    </visual>
    <collision>
      <origin
        xyz="0 0 0"
        rpy="0 0 0" />
      <geometry>
        <mesh
          filename="package://taurus_description/meshes/Caster_ball_link.STL" />
      </geometry>
    </collision>
  </link>
  <joint
    name="Caster_ball_joint"
    type="continuous">
    <origin
      xyz="0.31694 -0.080972 0.087994"
      rpy="-1.5864 0.022479 0.035052" />
    <parent
      link="base_link" />
    <child
      link="Caster_ball_link" />
    <axis
      xyz="1 1 1" />
  </joint>
</robot>