<?xml version="1.0" encoding="utf-8"?>
<!-- This URDF was automatically created by SolidWorks to URDF Exporter! Originally created by Stephen Brawner (brawner@gmail.com) 
     Commit Version: 1.6.0-4-g7f85cfe  Build Version: 1.6.7995.38578
     For more information, please see http://wiki.ros.org/sw_urdf_exporter -->
<robot
  name="taurus_description">
  <link
    name="base_link">
    <inertial>
      <origin
        xyz="0.000110504329843525 -0.000171267807196562 0.0164534041997902"
        rpy="0 0 0" />
      <mass
        value="0.100894161837639" />
      <inertia
        ixx="6.23159243909563E-05"
        ixy="3.4708905158842E-07"
        ixz="-3.66941191814054E-07"
        iyy="8.42380010312428E-05"
        iyz="-9.81180362076178E-08"
        izz="0.000143635833383964" />
    </inertial>
    <visual>
      <origin
        xyz="0 0 0"
        rpy="0 0 0" />
      <geometry>
        <mesh
          filename="package://taurus_description/meshes/base_link.STL" />
      </geometry>
      <material
        name="">
        <color
          rgba="0.792156862745098 0.819607843137255 0.933333333333333 1" />
      </material>
    </visual>
    <collision>
      <origin
        xyz="0 0 0"
        rpy="0 0 0" />
      <geometry>
        <mesh
          filename="package://taurus_description/meshes/base_link.STL" />
      </geometry>
    </collision>
  </link>
  <link
    name="rueda_derecha_link">
    <inertial>
      <origin
        xyz="1.72126556004931E-07 0.000106599449104558 -0.00113412741582314"
        rpy="0 0 0" />
      <mass
        value="0.0193884068569418" />
      <inertia
        ixx="2.05087981388653E-06"
        ixy="-4.22772499513206E-12"
        ixz="-7.10367193781474E-11"
        iyy="2.06483278978381E-06"
        iyz="-6.07029436396751E-09"
        izz="2.4409151355555E-06" />
    </inertial>
    <visual>
      <origin
        xyz="0 0 0"
        rpy="0 0 0" />
      <geometry>
        <mesh
          filename="package://taurus_description/meshes/rueda_derecha_link.STL" />
      </geometry>
      <material
        name="">
        <color
          rgba="0.666666666666667 0.698039215686274 0.768627450980392 1" />
      </material>
    </visual>
    <collision>
      <origin
        xyz="0 0 0"
        rpy="0 0 0" />
      <geometry>
        <mesh
          filename="package://taurus_description/meshes/rueda_derecha_link.STL" />
      </geometry>
    </collision>
  </link>
  <joint
    name="rueda_derecha_joint"
    type="continuous">
    <origin
      xyz="-0.0043022 -0.049462 0.0080355"
      rpy="-1.5723 0 0" />
    <parent
      link="base_link" />
    <child
      link="rueda_derecha_link" />
    <axis
      xyz="0 0 1" />
  </joint>
  <link
    name="rueda_izquierda_link">
    <inertial>
      <origin
        xyz="0.000104707279388615 -1.72015628169264E-06 0.00113430238217332"
        rpy="0 0 0" />
      <mass
        value="0.0193884068569417" />
      <inertia
        ixx="2.06481358280928E-06"
        ixy="-1.34219711089538E-11"
        ixz="5.44284283783669E-09"
        iyy="2.05088066244626E-06"
        iyz="-5.79681247521152E-10"
        izz="2.4409334939703E-06" />
    </inertial>
    <visual>
      <origin
        xyz="0 0 0"
        rpy="0 0 0" />
      <geometry>
        <mesh
          filename="package://taurus_description/meshes/rueda_izquierda_link.STL" />
      </geometry>
      <material
        name="">
        <color
          rgba="0.298039215686275 0.298039215686275 0.298039215686275 1" />
      </material>
    </visual>
    <collision>
      <origin
        xyz="0 0 0"
        rpy="0 0 0" />
      <geometry>
        <mesh
          filename="package://taurus_description/meshes/rueda_izquierda_link.STL" />
      </geometry>
    </collision>
  </link>
  <joint
    name="rueda_izquierda_joint"
    type="continuous">
    <origin
      xyz="-0.0043314 0.04838 0.0080163"
      rpy="-1.5723 0 0" />
    <parent
      link="base_link" />
    <child
      link="rueda_izquierda_link" />
    <axis
      xyz="0 0 1" />
  </joint>
  <link
    name="base_castor_link">
    <inertial>
      <origin
        xyz="2.36675372452672E-05 0.000188155199999596 -0.000655761496261356"
        rpy="0 0 0" />
      <mass
        value="0.000400871675159834" />
      <inertia
        ixx="7.28329410535018E-09"
        ixy="-3.57474531215572E-12"
        ixz="1.17752477041923E-11"
        iyy="6.6841814353447E-09"
        iyz="1.67236062399536E-10"
        izz="1.04009418882084E-08" />
    </inertial>
    <visual>
      <origin
        xyz="0 0 0"
        rpy="0 0 0" />
      <geometry>
        <mesh
          filename="package://taurus_description/meshes/base_castor_link.STL" />
      </geometry>
      <material
        name="">
        <color
          rgba="0 0 0 1" />
      </material>
    </visual>
    <collision>
      <origin
        xyz="0 0 0"
        rpy="0 0 0" />
      <geometry>
        <mesh
          filename="package://taurus_description/meshes/base_castor_link.STL" />
      </geometry>
    </collision>
  </link>
  <joint
    name="base_castor_joint"
    type="fixed">
    <origin
      xyz="0.05652 5.8287E-05 0.0034304"
      rpy="-0.0014807 0 0" />
    <parent
      link="base_link" />
    <child
      link="base_castor_link" />
    <axis
      xyz="0 0 0" />
  </joint>
  <link
    name="ball_Link">
    <inertial>
      <origin
        xyz="0 0 5.55111512312578E-17"
        rpy="0 0 0" />
      <mass
        value="0.000421160340343921" />
      <inertia
        ixx="3.64261578363457E-09"
        ixy="5.16987882845642E-26"
        ixz="-5.03672858165847E-26"
        iyy="3.64261578363457E-09"
        iyz="5.87251498786396E-27"
        izz="3.64261578363457E-09" />
    </inertial>
    <visual>
      <origin
        xyz="0 0 0"
        rpy="0 0 0" />
      <geometry>
        <mesh
          filename="package://taurus_description/meshes/ball_Link.STL" />
      </geometry>
      <material
        name="">
        <color
          rgba="1 1 1 1" />
      </material>
    </visual>
    <collision>
      <origin
        xyz="0 0 0"
        rpy="0 0 0" />
      <geometry>
        <mesh
          filename="package://taurus_description/meshes/ball_Link.STL" />
      </geometry>
    </collision>
  </link>
  <joint
    name="ball_joint"
    type="revolute">
    <origin
      xyz="-1.2745E-05 5.0515E-05 -0.0041208"
      rpy="-1.5708 0.022593 0" />
    <parent
      link="base_castor_link" />
    <child
      link="ball_Link" />
    <axis
      xyz="0 1 0" />
    <limit
      lower="0"
      upper="0"
      effort="0"
      velocity="0" />
  </joint>
  <link
    name="front_link">
    <inertial>
      <origin
        xyz="-0.00701507305162563 -0.0170033582422705 -0.000892738968458873"
        rpy="0 0 0" />
      <mass
        value="0.00557152535083265" />
      <inertia
        ixx="5.64875978418685E-07"
        ixy="-1.58184844673073E-09"
        ixz="3.63584874588953E-08"
        iyy="6.47495103109609E-07"
        iyz="6.65120859251812E-10"
        izz="2.35917953578526E-07" />
    </inertial>
    <visual>
      <origin
        xyz="0 0 0"
        rpy="0 0 0" />
      <geometry>
        <mesh
          filename="package://taurus_description/meshes/front_link.STL" />
      </geometry>
      <material
        name="">
        <color
          rgba="0.792156862745098 0.819607843137255 0.933333333333333 1" />
      </material>
    </visual>
    <collision>
      <origin
        xyz="0 0 0"
        rpy="0 0 0" />
      <geometry>
        <mesh
          filename="package://taurus_description/meshes/front_link.STL" />
      </geometry>
    </collision>
  </link>
  <joint
    name="front_joint"
    type="fixed">
    <origin
      xyz="0.056507 0.0001027 -0.00069056"
      rpy="-1.5723 0.022593 -3.3458E-05" />
    <parent
      link="base_link" />
    <child
      link="front_link" />
    <axis
      xyz="0 0 0" />
  </joint>
  <link
    name="der_link">
    <inertial>
      <origin
        xyz="-0.0222400014983548 -0.0156710385548851 -0.0356208355625536"
        rpy="0 0 0" />
      <mass
        value="0.00447834048846324" />
      <inertia
        ixx="9.32597625482861E-08"
        ixy="6.21089996882111E-09"
        ixz="4.80770767750181E-09"
        iyy="3.8251622391626E-07"
        iyz="-7.82785766002733E-11"
        izz="3.81164762413597E-07" />
    </inertial>
    <visual>
      <origin
        xyz="0 0 0"
        rpy="0 0 0" />
      <geometry>
        <mesh
          filename="package://taurus_description/meshes/der_link.STL" />
      </geometry>
      <material
        name="">
        <color
          rgba="0.0980392156862745 0.0980392156862745 0.0980392156862745 1" />
      </material>
    </visual>
    <collision>
      <origin
        xyz="0 0 0"
        rpy="0 0 0" />
      <geometry>
        <mesh
          filename="package://taurus_description/meshes/der_link.STL" />
      </geometry>
    </collision>
  </link>
  <joint
    name="der_joint"
    type="fixed">
    <origin
      xyz="0.056507 0.0001027 -0.00069056"
      rpy="-1.5723 0.022593 -3.3458E-05" />
    <parent
      link="base_link" />
    <child
      link="der_link" />
    <axis
      xyz="0 0 0" />
  </joint>
  <link
    name="izq_link">
    <inertial>
      <origin
        xyz="-0.0223136313523252 0.0354310139639194 0.0121590650094822"
        rpy="0 0 0" />
      <mass
        value="0.00447834047903675" />
      <inertia
        ixx="9.31273703823107E-08"
        ixy="4.80794907961316E-09"
        ixz="5.15742601559754E-10"
        iyy="3.81164603005841E-07"
        iyz="1.09454363636539E-11"
        izz="3.82648773188072E-07" />
    </inertial>
    <visual>
      <origin
        xyz="0 0 0"
        rpy="0 0 0" />
      <geometry>
        <mesh
          filename="package://taurus_description/meshes/izq_link.STL" />
      </geometry>
      <material
        name="">
        <color
          rgba="0.0980392156862745 0.0980392156862745 0.0980392156862745 1" />
      </material>
    </visual>
    <collision>
      <origin
        xyz="0 0 0"
        rpy="0 0 0" />
      <geometry>
        <mesh
          filename="package://taurus_description/meshes/izq_link.STL" />
      </geometry>
    </collision>
  </link>
  <joint
    name="izq_joint"
    type="fixed">
    <origin
      xyz="0.05652 5.8287E-05 0.0034304"
      rpy="-0.0014807 0 0" />
    <parent
      link="base_link" />
    <child
      link="izq_link" />
    <axis
      xyz="0 0 0" />
  </joint>
</robot>