<?xml version="1.0" encoding="utf-8"?>
<!-- This URDF was automatically created by SolidWorks to URDF Exporter! Originally created by Stephen Brawner (brawner@gmail.com) 
     Commit Version: 1.6.0-4-g7f85cfe  Build Version: 1.6.7995.38578
     For more information, please see http://wiki.ros.org/sw_urdf_exporter -->
<robot
  name="taurus_description">
  <link
    name="base_link">
    <inertial>
      <origin
        xyz="0.00293768617847149 -0.000180932444542536 0.0163820289331232"
        rpy="0 0 0" />
      <mass
        value="0.109923704165007" />
      <inertia
        ixx="6.25023471997517E-05"
        ixy="3.57248183955068E-07"
        ixz="-3.65582256475088E-07"
        iyy="8.50009197810057E-05"
        iyz="-1.86085775017922E-07"
        izz="0.00014440100030123" />
    </inertial>
    <visual>
      <origin
        xyz="0 0 0"
        rpy="0 0 0" />
      <geometry>
        <mesh
          filename="package://taurus_description/meshes/base_link.STL" />
      </geometry>
      <material
        name="">
        <color
          rgba="0.745098039215686 0.737254901960784 0.729411764705882 1" />
      </material>
    </visual>
    <collision>
      <origin
        xyz="0 0 0"
        rpy="0 0 0" />
      <geometry>
        <mesh
          filename="package://taurus_description/meshes/base_link.STL" />
      </geometry>
    </collision>
  </link>
  <link
    name="Rueda_derecha_link">
    <inertial>
      <origin
        xyz="-2.2882E-06 5.0601E-05 0.012107"
        rpy="0 0 0" />
      <mass
        value="0.010873" />
      <inertia
        ixx="1.1758E-06"
        ixy="-1.2262E-12"
        ixz="-6.3889E-11"
        iyy="1.181E-06"
        iyz="-2.5158E-09"
        izz="1.5164E-06" />
    </inertial>
    <visual>
      <origin
        xyz="0 0 0"
        rpy="0 0 0" />
      <geometry>
        <mesh
          filename="package://taurus_description/meshes/Rueda_derecha_link.STL" />
      </geometry>
      <material
        name="">
        <color
          rgba="0.29804 0.29804 0.29804 1" />
      </material>
    </visual>
    <collision>
      <origin
        xyz="0 0 0"
        rpy="0 0 0" />
      <geometry>
        <mesh
          filename="package://taurus_description/meshes/Rueda_derecha_link.STL" />
      </geometry>
    </collision>
  </link>
  <joint
    name="Rueda_derecha_joint"
    type="continuous">
    <origin
      xyz="-0.0043003 -0.059687 0.0079472"
      rpy="-1.5708 0 0" />
    <parent
      link="base_link" />
    <child
      link="Rueda_derecha_link" />
    <axis
      xyz="0 0 1" />
  </joint>
  <link
    name="Rueda_izquierda_link">
    <inertial>
      <origin
        xyz="-2.07606658204212E-06 -8.47789191934789E-05 0.0109759135877527"
        rpy="0 0 0" />
      <mass
        value="0.0108729816653414" />
      <inertia
        ixx="1.17584668229313E-06"
        ixy="2.17155732144836E-12"
        ixz="-6.38990967880419E-11"
        iyy="1.1809567264223E-06"
        iyz="-2.51582045690744E-09"
        izz="1.51643706988961E-06" />
    </inertial>
    <visual>
      <origin
        xyz="0 0 0"
        rpy="0 0 0" />
      <geometry>
        <mesh
          filename="package://taurus_description/meshes/Rueda_izquierda_link.STL" />
      </geometry>
      <material
        name="">
        <color
          rgba="0.298039215686275 0.298039215686275 0.298039215686275 1" />
      </material>
    </visual>
    <collision>
      <origin
        xyz="0 0 0"
        rpy="0 0 0" />
      <geometry>
        <mesh
          filename="package://taurus_description/meshes/Rueda_izquierda_link.STL" />
      </geometry>
    </collision>
  </link>
  <joint
    name="Rueda_izquierda_joint"
    type="continuous">
    <origin
      xyz="-0.0043291 0.036579 0.0080704"
      rpy="-1.5708 0 0" />
    <parent
      link="base_link" />
    <child
      link="Rueda_izquierda_link" />
    <axis
      xyz="0 0 1" />
  </joint>
  <link
    name="Scan_link">
    <inertial>
      <origin
        xyz="0.0100585530150035 -0.00088382028042483 0.000124001180761196"
        rpy="0 0 0" />
      <mass
        value="0.00557152535083265" />
      <inertia
        ixx="5.6498959667195E-07"
        ixy="3.6334182590303E-08"
        ixz="3.44621183831953E-09"
        iyy="2.35917953578526E-07"
        iyz="-1.48632821092049E-09"
        izz="6.47381484856345E-07" />
    </inertial>
    <visual>
      <origin
        xyz="0 0 0"
        rpy="0 0 0" />
      <geometry>
        <mesh
          filename="package://taurus_description/meshes/Scan_link.STL" />
      </geometry>
      <material
        name="">
        <color
          rgba="0.792156862745098 0.819607843137255 0.933333333333333 1" />
      </material>
    </visual>
    <collision>
      <origin
        xyz="0 0 0"
        rpy="0 0 0" />
      <geometry>
        <mesh
          filename="package://taurus_description/meshes/Scan_link.STL" />
      </geometry>
    </collision>
  </link>
  <joint
    name="Scan_joint"
    type="fixed">
    <origin
      xyz="0.03982 9.4804E-05 0.016343"
      rpy="0 0 0" />
    <parent
      link="base_link" />
    <child
      link="Scan_link" />
    <axis
      xyz="0 0 0" />
  </joint>
  <link
    name="Base_castor_link">
    <inertial>
      <origin
        xyz="-3.31048703354486E-06 -0.000199629661480183 -0.00106218045996687"
        rpy="0 0 0" />
      <mass
        value="0.00033462643989851" />
      <inertia
        ixx="6.91930126960993E-09"
        ixy="-9.21765842192387E-14"
        ixz="1.08783558404736E-11"
        iyy="6.32116285244819E-09"
        iyz="-1.78877539849884E-10"
        izz="1.03275741701081E-08" />
    </inertial>
    <visual>
      <origin
        xyz="0 0 0"
        rpy="0 0 0" />
      <geometry>
        <mesh
          filename="package://taurus_description/meshes/Base_castor_link.STL" />
      </geometry>
      <material
        name="">
        <color
          rgba="0 0 0 1" />
      </material>
    </visual>
    <collision>
      <origin
        xyz="0 0 0"
        rpy="0 0 0" />
      <geometry>
        <mesh
          filename="package://taurus_description/meshes/Base_castor_link.STL" />
      </geometry>
    </collision>
  </link>
  <joint
    name="Base_castor_joint"
    type="fixed">
    <origin
      xyz="0.056575 0 0.0034302"
      rpy="0 0 0" />
    <parent
      link="base_link" />
    <child
      link="Base_castor_link" />
    <axis
      xyz="0 0 0" />
  </joint>
  <link
    name="Caster_ball_link">
    <inertial>
      <origin
        xyz="0 0 0"
        rpy="0 0 0" />
      <mass
        value="0" />
      <inertia
        ixx="0"
        ixy="0"
        ixz="0"
        iyy="0"
        iyz="0"
        izz="0" />
    </inertial>
    <visual>
      <origin
        xyz="0 0 0"
        rpy="0 0 0" />
      <geometry>
        <mesh
          filename="package://taurus_description/meshes/Caster_ball_link.STL" />
      </geometry>
      <material
        name="">
        <color
          rgba="1 1 1 1" />
      </material>
    </visual>
    <collision>
      <origin
        xyz="0 0 0"
        rpy="0 0 0" />
      <geometry>
        <mesh
          filename="package://taurus_description/meshes/Caster_ball_link.STL" />
      </geometry>
    </collision>
  </link>
  <joint
    name="Caster_ball_joint"
    type="continuous">
    <origin
      xyz="0.056562 -3.4474E-05 -0.00069078"
      rpy="-1.5708 0 0" />
    <parent
      link="base_link" />
    <child
      link="Caster_ball_link" />
    <axis
      xyz="-0.0031952 0.99999 0.0014801" />
  </joint>
</robot>