<?xml version="1.0" encoding="utf-8"?>
<!-- This URDF was automatically created by SolidWorks to URDF Exporter! Originally created by Stephen Brawner (brawner@gmail.com) 
     Commit Version: 1.6.0-4-g7f85cfe  Build Version: 1.6.7995.38578
     For more information, please see http://wiki.ros.org/sw_urdf_exporter -->
<robot
  name="EnsambleRobot.SLDASM">
  <link
    name="base_link">
    <inertial>
      <origin
        xyz="0.00490709777806271 -0.000189801490740903 0.0158541076050414"
        rpy="0 0 0" />
      <mass
        value="0.113840294442823" />
      <inertia
        ixx="6.20713657332795E-05"
        ixy="3.73859938549769E-07"
        ixz="-2.92245316767897E-07"
        iyy="8.49118196111279E-05"
        iyz="-9.75716180324087E-08"
        izz="0.00014401772306779" />
    </inertial>
    <visual>
      <origin
        xyz="0 0 0"
        rpy="0 0 0" />
      <geometry>
        <mesh
          filename="package://EnsambleRobot.SLDASM/meshes/base_link.STL" />
      </geometry>
      <material
        name="">
        <color
          rgba="0.792156862745098 0.819607843137255 0.933333333333333 1" />
      </material>
    </visual>
    <collision>
      <origin
        xyz="0 0 0"
        rpy="0 0 0" />
      <geometry>
        <mesh
          filename="package://EnsambleRobot.SLDASM/meshes/base_link.STL" />
      </geometry>
    </collision>
  </link>
  <link
    name="L_wheel_link">
    <inertial>
      <origin
        xyz="-2.991E-05 0.00010441 0.010675"
        rpy="0 0 0" />
      <mass
        value="0.019388" />
      <inertia
        ixx="2.051E-06"
        ixy="-1.3818E-09"
        ixz="-1.2588E-09"
        iyy="2.0647E-06"
        iyz="5.4839E-09"
        izz="2.4409E-06" />
    </inertial>
    <visual>
      <origin
        xyz="0 0 0"
        rpy="0 0 0" />
      <geometry>
        <mesh
          filename="package://EnsambleRobot.SLDASM/meshes/L_wheel_link.STL" />
      </geometry>
      <material
        name="">
        <color
          rgba="0.66667 0.69804 0.76863 1" />
      </material>
    </visual>
    <collision>
      <origin
        xyz="0 0 0"
        rpy="0 0 0" />
      <geometry>
        <mesh
          filename="package://EnsambleRobot.SLDASM/meshes/L_wheel_link.STL" />
      </geometry>
    </collision>
  </link>
  <joint
    name="L_Wheel_joint"
    type="continuous">
    <origin
      xyz="-0.0043278 0.031199 0.0080157"
      rpy="-1.5708 0.0038917 -0.0016425" />
    <parent
      link="base_link" />
    <child
      link="L_wheel_link" />
    <axis
      xyz="0 0 1" />
  </joint>
  <link
    name="R_wheel_link">
    <inertial>
      <origin
        xyz="5.8089E-05 -8.7372E-05 -0.010675"
        rpy="0 0 0" />
      <mass
        value="0.019388" />
      <inertia
        ixx="2.0552E-06"
        ixy="-6.4251E-09"
        ixz="-3.0525E-09"
        iyy="2.0605E-06"
        iyz="4.5913E-09"
        izz="2.4409E-06" />
    </inertial>
    <visual>
      <origin
        xyz="0 0 0"
        rpy="0 0 0" />
      <geometry>
        <mesh
          filename="package://EnsambleRobot.SLDASM/meshes/R_wheel_link.STL" />
      </geometry>
      <material
        name="">
        <color
          rgba="0.66667 0.69804 0.76863 1" />
      </material>
    </visual>
    <collision>
      <origin
        xyz="0 0 0"
        rpy="0 0 0" />
      <geometry>
        <mesh
          filename="package://EnsambleRobot.SLDASM/meshes/R_wheel_link.STL" />
      </geometry>
    </collision>
  </link>
  <joint
    name="R_wheel_joint"
    type="continuous">
    <origin
      xyz="-0.0043053 -0.0312 0.008035"
      rpy="-1.5708 0 0.00018716" />
    <parent
      link="base_link" />
    <child
      link="R_wheel_link" />
    <axis
      xyz="0 0 1" />
  </joint>
  <link
    name="base_ball_link">
    <inertial>
      <origin
        xyz="-0.00015674 3.6616E-06 0.0017564"
        rpy="0 0 0" />
      <mass
        value="0.00033463" />
      <inertia
        ixx="6.321E-09"
        ixy="1.3819E-11"
        ixz="1.729E-10"
        iyy="6.9189E-09"
        iyz="-3.8417E-12"
        izz="1.0328E-08" />
    </inertial>
    <visual>
      <origin
        xyz="0 0 0"
        rpy="0 0 0" />
      <geometry>
        <mesh
          filename="package://EnsambleRobot.SLDASM/meshes/base_ball_link.STL" />
      </geometry>
      <material
        name="">
        <color
          rgba="0 0 0 1" />
      </material>
    </visual>
    <collision>
      <origin
        xyz="0 0 0"
        rpy="0 0 0" />
      <geometry>
        <mesh
          filename="package://EnsambleRobot.SLDASM/meshes/base_ball_link.STL" />
      </geometry>
    </collision>
  </link>
  <joint
    name="base_ball_joint"
    type="fixed">
    <origin
      xyz="0.056423 -3.722E-05 0.0031184"
      rpy="-3.1383 0 1.571" />
    <parent
      link="base_link" />
    <child
      link="base_ball_link" />
    <axis
      xyz="0 0 0" />
  </joint>
  <link
    name="foward_ball_link">
    <inertial>
      <origin
        xyz="0 6.9389E-18 3.4694E-18"
        rpy="0 0 0" />
      <mass
        value="0.00042116" />
      <inertia
        ixx="3.6426E-09"
        ixy="-1.2278E-25"
        ixz="1.2925E-26"
        iyy="3.6426E-09"
        iyz="-2.6253E-27"
        izz="3.6426E-09" />
    </inertial>
    <visual>
      <origin
        xyz="0 0 0"
        rpy="0 0 0" />
      <geometry>
        <mesh
          filename="package://EnsambleRobot.SLDASM/meshes/foward_ball_link.STL" />
      </geometry>
      <material
        name="">
        <color
          rgba="1 1 1 1" />
      </material>
    </visual>
    <collision>
      <origin
        xyz="0 0 0"
        rpy="0 0 0" />
      <geometry>
        <mesh
          filename="package://EnsambleRobot.SLDASM/meshes/foward_ball_link.STL" />
      </geometry>
    </collision>
  </link>
  <joint
    name="foward_ball_joint"
    type="continuous">
    <origin
      xyz="0 0 0.0048155"
      rpy="1.5467 0.018736 1.5131" />
    <parent
      link="base_ball_link" />
    <child
      link="foward_ball_link" />
    <axis
      xyz="0 0 1" />
  </joint>
  <link
    name="lateral_ball_link">
    <inertial>
      <origin
        xyz="0 0 1.3878E-17"
        rpy="0 0 0" />
      <mass
        value="0.00042116" />
      <inertia
        ixx="3.6426E-09"
        ixy="6.4623E-27"
        ixz="1.2925E-25"
        iyy="3.6426E-09"
        iyz="6.4623E-27"
        izz="3.6426E-09" />
    </inertial>
    <visual>
      <origin
        xyz="0 0 0"
        rpy="0 0 0" />
      <geometry>
        <mesh
          filename="package://EnsambleRobot.SLDASM/meshes/lateral_ball_link.STL" />
      </geometry>
      <material
        name="">
        <color
          rgba="1 1 1 1" />
      </material>
    </visual>
    <collision>
      <origin
        xyz="0 0 0"
        rpy="0 0 0" />
      <geometry>
        <mesh
          filename="package://EnsambleRobot.SLDASM/meshes/lateral_ball_link.STL" />
      </geometry>
    </collision>
  </link>
  <joint
    name="lateral_ball_joint"
    type="continuous">
    <origin
      xyz="0 0 0.0048155"
      rpy="-3.1416 -0.064409 1.5485" />
    <parent
      link="base_ball_link" />
    <child
      link="lateral_ball_link" />
    <axis
      xyz="0 0 1" />
  </joint>
</robot>