<?xml version="1.0" encoding="utf-8"?>
<!-- This URDF was automatically created by SolidWorks to URDF Exporter! Originally created by Stephen Brawner (brawner@gmail.com) 
     Commit Version: 1.6.0-4-g7f85cfe  Build Version: 1.6.7995.38578
     For more information, please see http://wiki.ros.org/sw_urdf_exporter -->
<robot
  name="taurus_description">
  <link
    name="base_link">
    <inertial>
      <origin
        xyz="0.003868358578296 -0.000158188357109068 0.0163891387106582"
        rpy="0 0 0" />
      <mass
        value="0.109739900930225" />
      <inertia
        ixx="6.20527220086167E-05"
        ixy="3.64237642737894E-07"
        ixz="-7.8808466840299E-07"
        iyy="8.58594312413681E-05"
        iyz="-9.68221357205741E-08"
        izz="0.000144845960814212" />
    </inertial>
    <visual>
      <origin
        xyz="0 0 0"
        rpy="0 0 0" />
      <geometry>
        <mesh
          filename="package://taurus_description/meshes/base_link.STL" />
      </geometry>
      <material
        name="">
        <color
          rgba="0.792156862745098 0.819607843137255 0.933333333333333 1" />
      </material>
    </visual>
    <collision>
      <origin
        xyz="0 0 0"
        rpy="0 0 0" />
      <geometry>
        <mesh
          filename="package://taurus_description/meshes/base_link.STL" />
      </geometry>
    </collision>
  </link>
  <link
    name="wheel_left_link">
    <inertial>
      <origin
        xyz="-2.0625E-05 -6.8524E-05 0.010935"
        rpy="0 0 0" />
      <mass
        value="0.010873" />
      <inertia
        ixx="1.1758E-06"
        ixy="4.9703E-11"
        ixz="-6.409E-10"
        iyy="1.1809E-06"
        iyz="-2.0189E-09"
        izz="1.5164E-06" />
    </inertial>
    <visual>
      <origin
        xyz="0 0 0"
        rpy="0 0 0" />
      <geometry>
        <mesh
          filename="package://taurus_description/meshes/wheel_left_link.STL" />
      </geometry>
      <material
        name="">
        <color
          rgba="0.29804 0.29804 0.29804 1" />
      </material>
    </visual>
    <collision>
      <origin
        xyz="0 0 0"
        rpy="0 0 0" />
      <geometry>
        <mesh
          filename="package://taurus_description/meshes/wheel_left_link.STL" />
      </geometry>
    </collision>
  </link>
  <joint
    name="wheel_left_joint"
    type="continuous">
    <origin
      xyz="-0.0033479 0.03711 0.0080001"
      rpy="-1.5708 0 -0.0018302" />
    <parent
      link="base_link" />
    <child
      link="wheel_left_link" />
    <axis
      xyz="0 0 1" />
    <limit
      effort="100"
      velocity="100" />
    <dynamics
      damping="0.1"
      friction="0.1" />
  </joint>
  <link
    name="wheel_right_link">
    <inertial>
      <origin
        xyz="2.1073E-05 6.8519E-05 -0.010935"
        rpy="0 0 0" />
      <mass
        value="0.010873" />
      <inertia
        ixx="1.1758E-06"
        ixy="8.2212E-11"
        ixz="-6.551E-10"
        iyy="1.1809E-06"
        iyz="-2.0187E-09"
        izz="1.5164E-06" />
    </inertial>
    <visual>
      <origin
        xyz="0 0 0"
        rpy="0 0 0" />
      <geometry>
        <mesh
          filename="package://taurus_description/meshes/wheel_right_link.STL" />
      </geometry>
      <material
        name="">
        <color
          rgba="0.89804 0.91765 0.92941 1" />
      </material>
    </visual>
    <collision>
      <origin
        xyz="0 0 0"
        rpy="0 0 0" />
      <geometry>
        <mesh
          filename="package://taurus_description/meshes/wheel_right_link.STL" />
      </geometry>
    </collision>
  </link>
  <joint
    name="wheel_right_joint"
    type="continuous">
    <origin
      xyz="-0.0033372 -0.037239 0.0080194"
      rpy="-1.5708 0 -0.0018302" />
    <parent
      link="base_link" />
    <child
      link="wheel_right_link" />
    <axis
      xyz="0 0 1" />
    <limit
      effort="100"
      velocity="100" />
    <dynamics
      damping="0.1"
      friction="0.1" />
  </joint>
  <link
    name="caster_ball_link">
    <inertial>
      <origin
        xyz="0 1.3878E-17 0"
        rpy="0 0 0" />
      <mass
        value="0.00042116" />
      <inertia
        ixx="3.6426E-09"
        ixy="-1.7771E-26"
        ixz="5.0487E-26"
        iyy="3.6426E-09"
        iyz="9.6919E-27"
        izz="3.6426E-09" />
    </inertial>
    <visual>
      <origin
        xyz="0 0 0"
        rpy="0 0 0" />
      <geometry>
        <mesh
          filename="package://taurus_description/meshes/caster_ball_link.STL" />
      </geometry>
      <material
        name="">
        <color
          rgba="1 1 1 1" />
      </material>
    </visual>
    <collision>
      <origin
        xyz="0 0 0"
        rpy="0 0 0" />
      <geometry>
        <mesh
          filename="package://taurus_description/meshes/caster_ball_link.STL" />
      </geometry>
    </collision>
  </link>
  <joint
    name="caster_ball_joint"
    type="continuous">
    <origin
      xyz="0.057569 -4.6108E-05 -0.00046991"
      rpy="-1.5708 0 -0.0018302" />
    <parent
      link="base_link" />
    <child
      link="caster_ball_link" />
    <axis
      xyz="0 0 1" />
    <limit
      effort="100"
      velocity="100" />
    <dynamics
      damping="0.1"
      friction="0.1" />
  </joint>
  <link
    name="scan_link">
    <inertial>
      <origin
        xyz="0 0 0"
        rpy="0 0 0" />
      <mass
        value="0" />
      <inertia
        ixx="0"
        ixy="0"
        ixz="0"
        iyy="0"
        iyz="0"
        izz="0" />
    </inertial>
    <visual>
      <origin
        xyz="0 0 0"
        rpy="0 0 0" />
      <geometry>
        <mesh
          filename="package://taurus_description/meshes/scan_link.STL" />
      </geometry>
      <material
        name="">
        <color
          rgba="1 1 1 1" />
      </material>
    </visual>
    <collision>
      <origin
        xyz="0 0 0"
        rpy="0 0 0" />
      <geometry>
        <mesh
          filename="package://taurus_description/meshes/scan_link.STL" />
      </geometry>
    </collision>
  </link>
  <joint
    name="scan_joint"
    type="fixed">
    <origin
      xyz="0.040761 0.00011153 0.016498"
      rpy="0 0 -0.0018302" />
    <parent
      link="base_link" />
    <child
      link="scan_link" />
    <axis
      xyz="0 0 0" />
    <dynamics
      damping="0.1"
      friction="0.1" />
  </joint>
</robot>